Workbook

Sheet Kalkulator
A1: Kalkulator - Biaya Kirim GEM
A3: Toko | D3: Blibli Elektronik - Kopo Bandung | F3: Pilih field ini - 1st
A4: Alamat Pengiriman
B5: Kota | D5: Kab. Bandung | F5: Pilih field ini - 2nd
B6: Kode Pos | D6: 40376 | F6: Pilih field ini - 3rd
A7: Tipe Pengiriman | D7: Nextday Delivery | F7: Pilih field ini - 4th
A8: Big Product (>35 Kg) | E8: Biaya Kirim - Customer
A9: Minimum Charge | D9: =INDEX(Sheet1!$F$12:$H$1468,MATCH(Kalkulator!$D$5&Kalkulator!$D$6,Sheet1!$A$12:$A$1468,0),MATCH(Kalkulator!$D$3,Sheet1!$F$11:$H$11,0)) -> ZONE 1 | E9: =D9 -> ZONE 1 | F9: Gratis Biaya Kirim untuk 7 Km dari toko - Bandung Blibli Elektronik
A10: Distance | E10: =ROUNDDOWN(INDEX(Distance!$D$4:$F$1460,MATCH(Kalkulator!$D$5&Kalkulator!$D$6,Distance!$A$4:$A$1460,0),MATCH(Kalkulator!$D$3,Distance!$D$3:$F$3,0)),0) -> 26 | F10: dan 10 Km dari toko - Bekasi Dekoruma Elektronik
B11: Kategori Produk | C11: QTY | D11: ShipCost charged by GDPa
B12: Dispenser | D12: =IF(OR($D$7="Trade In Delivery",$D$7="Lite Install Delivery"), IF($D$9="ZONE 1", IFERROR(_xlfn.IFNA(C12*INDEX(Sheet1!$U$12:$W$21,MATCH(Kalkulator!$B12,Sheet1!$T$12:$T$21,0),MATCH(Kalkulator!$D$7,Sheet1!$U$12:$W$12,0)),"Not Available"),"Not Available"),"Not Available"), IFERROR(_xlfn.IFNA(C12*INDEX(Sheet1!$U$12:$W$21,MATCH(Kalkulator!$B12,Sheet1!$T$12:$T$21,0),MATCH(Kalkulator!$D$7,Sheet1!$U$12:$W$12,0)),"Not Available"),"Not Available")) -> 0 | E12: =D12 -> 0
B13: Home Theather | D13: =IF(OR($D$7="Trade In Delivery",$D$7="Lite Install Delivery"), IF($D$9="ZONE 1", IFERROR(_xlfn.IFNA(C13*INDEX(Sheet1!$U$12:$W$21,MATCH(Kalkulator!$B13,Sheet1!$T$12:$T$21,0),MATCH(Kalkulator!$D$7,Sheet1!$U$12:$W$12,0)),"Not Available"),"Not Available"),"Not Available"), IFERROR(_xlfn.IFNA(C13*INDEX(Sheet1!$U$12:$W$21,MATCH(Kalkulator!$B13,Sheet1!$T$12:$T$21,0),MATCH(Kalkulator!$D$7,Sheet1!$U$12:$W$12,0)),"Not Available"),"Not Available")) -> 0 | E13: =D13 -> 0
B14: Water Heater | D14: =IF(OR($D$7="Trade In Delivery",$D$7="Lite Install Delivery"), IF($D$9="ZONE 1", IFERROR(_xlfn.IFNA(C14*INDEX(Sheet1!$U$12:$W$21,MATCH(Kalkulator!$B14,Sheet1!$T$12:$T$21,0),MATCH(Kalkulator!$D$7,Sheet1!$U$12:$W$12,0)),"Not Available"),"Not Available"),"Not Available"), IFERROR(_xlfn.IFNA(C14*INDEX(Sheet1!$U$12:$W$21,MATCH(Kalkulator!$B14,Sheet1!$T$12:$T$21,0),MATCH(Kalkulator!$D$7,Sheet1!$U$12:$W$12,0)),"Not Available"),"Not Available")) -> 0 | E14: =D14 -> 0
B15: TV (<= 43") | D15: =IF(OR($D$7="Trade In Delivery",$D$7="Lite Install Delivery"), IF($D$9="ZONE 1", IFERROR(_xlfn.IFNA(C15*INDEX(Sheet1!$U$12:$W$21,MATCH(Kalkulator!$B15,Sheet1!$T$12:$T$21,0),MATCH(Kalkulator!$D$7,Sheet1!$U$12:$W$12,0)),"Not Available"),"Not Available"),"Not Available"), IFERROR(_xlfn.IFNA(C15*INDEX(Sheet1!$U$12:$W$21,MATCH(Kalkulator!$B15,Sheet1!$T$12:$T$21,0),MATCH(Kalkulator!$D$7,Sheet1!$U$12:$W$12,0)),"Not Available"),"Not Available")) -> 0 | E15: =D15 -> 0
B16: TV (> 43") | D16: =IF(OR($D$7="Trade In Delivery",$D$7="Lite Install Delivery"), IF($D$9="ZONE 1", IFERROR(_xlfn.IFNA(C16*INDEX(Sheet1!$U$12:$W$21,MATCH(Kalkulator!$B16,Sheet1!$T$12:$T$21,0),MATCH(Kalkulator!$D$7,Sheet1!$U$12:$W$12,0)),"Not Available"),"Not Available"),"Not Available"), IFERROR(_xlfn.IFNA(C16*INDEX(Sheet1!$U$12:$W$21,MATCH(Kalkulator!$B16,Sheet1!$T$12:$T$21,0),MATCH(Kalkulator!$D$7,Sheet1!$U$12:$W$12,0)),"Not Available"),"Not Available")) -> 0 | E16: =D16 -> 0
B17: Mesin Cuci | D17: =IF(OR($D$7="Trade In Delivery",$D$7="Lite Install Delivery"), IF($D$9="ZONE 1", IFERROR(_xlfn.IFNA(C17*INDEX(Sheet1!$U$12:$W$21,MATCH(Kalkulator!$B17,Sheet1!$T$12:$T$21,0),MATCH(Kalkulator!$D$7,Sheet1!$U$12:$W$12,0)),"Not Available"),"Not Available"),"Not Available"), IFERROR(_xlfn.IFNA(C17*INDEX(Sheet1!$U$12:$W$21,MATCH(Kalkulator!$B17,Sheet1!$T$12:$T$21,0),MATCH(Kalkulator!$D$7,Sheet1!$U$12:$W$12,0)),"Not Available"),"Not Available")) -> 0 | E17: =D17 -> 0
B18: AC | D18: =IF(OR($D$7="Trade In Delivery",$D$7="Lite Install Delivery"), IF($D$9="ZONE 1", IFERROR(_xlfn.IFNA(C18*INDEX(Sheet1!$U$12:$W$21,MATCH(Kalkulator!$B18,Sheet1!$T$12:$T$21,0),MATCH(Kalkulator!$D$7,Sheet1!$U$12:$W$12,0)),"Not Available"),"Not Available"),"Not Available"), IFERROR(_xlfn.IFNA(C18*INDEX(Sheet1!$U$12:$W$21,MATCH(Kalkulator!$B18,Sheet1!$T$12:$T$21,0),MATCH(Kalkulator!$D$7,Sheet1!$U$12:$W$12,0)),"Not Available"),"Not Available")) -> 0 | E18: =D18 -> 0
B19: Kulkas (<320Lt) | D19: =IF(OR($D$7="Trade In Delivery",$D$7="Lite Install Delivery"), IF($D$9="ZONE 1", IFERROR(_xlfn.IFNA(C19*INDEX(Sheet1!$U$12:$W$21,MATCH(Kalkulator!$B19,Sheet1!$T$12:$T$21,0),MATCH(Kalkulator!$D$7,Sheet1!$U$12:$W$12,0)),"Not Available"),"Not Available"),"Not Available"), IFERROR(_xlfn.IFNA(C19*INDEX(Sheet1!$U$12:$W$21,MATCH(Kalkulator!$B19,Sheet1!$T$12:$T$21,0),MATCH(Kalkulator!$D$7,Sheet1!$U$12:$W$12,0)),"Not Available"),"Not Available")) -> 0 | E19: =D19 -> 0
B20: Kulkas (320Lt - Side by Side) | D20: =IF(OR($D$7="Trade In Delivery",$D$7="Lite Install Delivery"), IF($D$9="ZONE 1", IFERROR(_xlfn.IFNA(C20*INDEX(Sheet1!$U$12:$W$21,MATCH(Kalkulator!$B20,Sheet1!$T$12:$T$21,0),MATCH(Kalkulator!$D$7,Sheet1!$U$12:$W$12,0)),"Not Available"),"Not Available"),"Not Available"), IFERROR(_xlfn.IFNA(C20*INDEX(Sheet1!$U$12:$W$21,MATCH(Kalkulator!$B20,Sheet1!$T$12:$T$21,0),MATCH(Kalkulator!$D$7,Sheet1!$U$12:$W$12,0)),"Not Available"),"Not Available")) -> 0 | E20: =D20 -> 0
A21: Total Biaya Kirim | D21: =IF(D9="ZONE 1",SUM(D12:D20),IF(SUM(D12:D20)>D9,SUM(D12:D20),D9)) -> 0 | E21: {=IF(E10<=INDEX(Distance!$D$2:$F$2,,MATCH(Kalkulator!$D$3,Distance!$D$3:$F$3,0)),"FREE SHIPPING",IF(E9="ZONE 1",SUM(E12:E20),IF(SUM(E12:E20)>E9,SUM(E12:E20),E9)))} -> 0

Sheet ShipTable Coverage n Min Charge
D3: Distance from | G3: Minimum Charge | L3: Distance from | M3: Minimum Charge
A4: Province | B4: City | C4: Postal Code | D4: WH Bandung | E4: Blibli Elektronik - Kopo Bandung | F4: Blibli Elektronik - Banjaran Bandung | G4: Blibli Elektronik Bandung | I4: Province | J4: City | K4: Postal Code | L4: =M4 -> Dekoruma Elektronik - Kalimalang Bekasi | M4: Dekoruma Elektronik - Kalimalang Bekasi
A5: Jawa Barat | B5: Kab. Bandung | C5: 40191 | D5: 9.2549933 | E5: 14.638923 | F5: 22.040648 | G5: ZONE 1 | I5: Jawa Barat | J5: Kota Bekasi | K5: 17145 | L5: 1.8359805 | M5: ZONE 1
A6: Jawa Barat | B6: Kab. Bandung | C6: 40193 | D6: 11.708879 | E6: 19.414139 | F6: 25.0477 | G6: ZONE 1 | I6: Jawa Barat | J6: Kota Bekasi | K6: 17136 | L6: 2.0726321 | M6: ZONE 1
A7: Jawa Barat | B7: Kab. Bandung | C7: 40195 | D7: 8.0819019 | E7: 16.745119 | F7: 21.274082 | G7: ZONE 1 | I7: Jawa Barat | J7: Kota Bekasi | K7: 17412 | L7: 3.3412314 | M7: ZONE 1
A8: Jawa Barat | B8: Kab. Bandung | C8: 40196 | D8: 16.015679 | E8: 24.21207 | F8: 29.188117 | G8: ZONE 1 | I8: Jawa Barat | J8: Kota Bekasi | K8: 17134 | L8: 3.4909868 | M8: ZONE 1
A9: Jawa Barat | B9: Kab. Bandung | C9: 40197 | D9: 14.172819 | E9: 21.209476 | F9: 27.512772 | G9: ZONE 1 | I9: Jawa Barat | J9: Kota Bekasi | K9: 17146 | L9: 3.5676845 | M9: ZONE 1
A10: Jawa Barat | B10: Kab. Bandung | C10: 40198 | D10: 12.829213 | E10: 18.627884 | F10: 25.909671 | G10: ZONE 1 | I10: Jawa Barat | J10: Kota Bekasi | K10: 17135 | L10: 4.2495175 | M10: ZONE 1
A11: Jawa Barat | B11: Kab. Bandung | C11: 40214 | D11: 14.541253 | E11: 5.2898497 | F11: 14.330216 | G11: ZONE 1 | I11: Jawa Barat | J11: Kota Bekasi | K11: 17148 | L11: 4.4546828 | M11: ZONE 1
A12: Jawa Barat | B12: Kab. Bandung | C12: 40216 | D12: 18.229069 | E12: 9.7833196 | F12: 19.074959 | G12: ZONE 1 | I12: DKI Jakarta | J12: Kota Jakarta Timur | K12: 13460 | L12: 4.5704519 | M12: ZONE 1
A13: Jawa Barat | B13: Kab. Bandung | C13: 40218 | D13: 15.091519 | E13: 5.5559618 | F13: 11.601678 | G13: ZONE 1 | I13: DKI Jakarta | J13: Kota Jakarta Timur | K13: 13450 | L13: 4.6912624 | M13: ZONE 1
A14: Jawa Barat | B14: Kab. Bandung | C14: 40225 | D14: 12.031674 | E14: 2.431313 | F14: 10.913973 | G14: ZONE 1 | I14: Jawa Barat | J14: Kota Bekasi | K14: 17144 | L14: 4.891005 | M14: ZONE 1
A15: Jawa Barat | B15: Kab. Bandung | C15: 40226 | D15: 13.713108 | E15: 4.4935312 | F15: 9.9225949 | G15: ZONE 1 | I15: Jawa Barat | J15: Kota Bekasi | K15: 17133 | L15: 5.1376739 | M15: ZONE 1
A16: Jawa Barat | B16: Kab. Bandung | C16: 40227 | D16: 10.831675 | E16: 2.608778 | F16: 8.4614898 | G16: ZONE 1 | I16: Jawa Barat | J16: Kota Bekasi | K16: 17421 | L16: 5.5069027 | M16: ZONE 1
... A164: Jawa Barat | B164: Kota Cimahi | C164: 40535 | D164: 14.579981 | E164: 8.581413 | F164: 19.182746 | G164: ZONE 1 | I164: DKI Jakarta | J164: Kota Jakarta Selatan | K164: 12710 | L164: 22.451607 | M164: ZONE 1
A165: Jawa Barat | B165: Kab. Bandung | C165: 40267 | D165: 5.3638834 | E165: 7.7365421 | F165: 7.9858895 | G165: 165000 | I165: DKI Jakarta | J165: Kota Jakarta Utara | K165: 14230 | L165: 22.492893 | M165: ZONE 1
A166: Jawa Barat | B166: Kab. Bandung | C166: 40217 | D166: 17.708364 | E166: 8.1504211 | F166: 15.229479 | G166: 225000 | I166: DKI Jakarta | J166: Kota Jakarta Selatan | K166: 12540 | L166: 22.636652 | M166: ZONE 1
A167: Jawa Barat | B167: Kab. Bandung | C167: 40379 | D167: 20.927723 | E167: 19.993067 | F167: 9.3397437 | G167: 240000 | I167: DKI Jakarta | J167: Kota Jakarta Pusat | K167: 10410 | L167: 22.641422 | M167: ZONE 1
A168: Jawa Barat | B168: Kab. Bandung Barat | C168: 40391 | D168: 20.644678 | E168: 25.790033 | F168: 33.672207 | G168: 240000 | I168: DKI Jakarta | J168: Kota Jakarta Pusat | K168: 10630 | L168: 22.722834 | M168: ZONE 1
A169: Jawa Barat | B169: Kab. Bandung | C169: 40394 | D169: 22.890208 | E169: 31.55307 | F169: 27.895842 | G169: 250000 | I169: DKI Jakarta | J169: Kota Jakarta Pusat | K169: 10350 | L169: 22.767396 | M169: ZONE 1
A170: Jawa Barat | B170: Kab. Bandung | C170: 40238 | D170: 24.858141 | E170: 17.785879 | F170: 12.809321 | G170: 260000 | I170: DKI Jakarta | J170: Kota Jakarta Timur | K170: 13790 | L170: 22.803422 | M170: ZONE 1
A171: Jawa Barat | B171: Kab. Sumedang | C171: 45366 | D171: 24.611745 | E171: 34.090895 | F171: 35.806745 | G171: 260000 | I171: DKI Jakarta | J171: Kota Jakarta Selatan | K171: 12910 | L171: 22.813449 | M171: ZONE 1
A172: Jawa Barat | B172: Kab. Bandung | C172: 40377 | D172: 25.151492 | E172: 21.278046 | F172: 11.856312 | G172: 265000 | I172: DKI Jakarta | J172: Kota Jakarta Selatan | K172: 12730 | L172: 22.859796 | M172: ZONE 1
A173: Jawa Barat | B173: Kab. Bandung | C173: 40382 | D173: 25.646406 | E173: 31.060051 | F173: 23.031906 | G173: 265000 | I173: DKI Jakarta | J173: Kota Jakarta Selatan | K173: 12520 | L173: 22.957377 | M173: ZONE 1
A174: Jawa Barat | B174: Kab. Bandung Barat | C174: 40392 | D174: 25.794332 | E174: 31.323952 | F174: 23.386047 | G174: 265000 | I174: DKI Jakarta | J174: Kota Jakarta Pusat | K174: 10620 | L174: 23.026984 | M174: ZONE 1
A175: Jawa Barat | B175: Kab. Bandung Barat | C175: 40552 | D175: 26.84907 | E175: 21.873142 | F175: 32.341239 | G175: 270000 | I175: DKI Jakarta | J175: Kota Jakarta Selatan | K175: 12920 | L175: 23.060034 | M175: ZONE 1
A176: Jawa Barat | B176: Kab. Bandung | C176: 40374 | D176: 27.861338 | E176: 22.045091 | F176: 14.750302 | G176: 275000 | I176: Jawa Barat | J176: Kab. Bogor | K176: 16967 | L176: 23.108962 | M176: ZONE 1
... A574: Jawa Barat | B574: Kab. Kuningan | C574: 45517 | D574: 139.65476 | E574: 148.89504 | F574: 144.98611 | G574: 835000 | I574: Jawa Barat | J574: Kab. Bogor | K574: 16660 | L574: 102.66483 | M574: ZONE 1
A575: Jawa Barat | B575: Kab. Kuningan | C575: 45566 | D575: 139.73989 | E575: 148.40685 | F575: 142.92986 | G575: 835000 | I575: Jawa Barat | J575: Kab. Bogor | K575: 16119 | L575: 66.299902 | M575: 315000
A576: Jawa Barat | B576: Kab. Bogor | C576: 16710 | D576: 140.3101 | E576: 133.9118 | F576: 143.02503 | G576: 840000 | I576: Jawa Barat | J576: Kab. Cianjur | K576: 43253 | L576: 81.875026 | M576: 440000
A577: Jawa Barat | B577: Kab. Cirebon | C577: 45611 | D577: 140.93989 | E577: 150.5508 | F577: 149.02956 | G577: 840000 | I577: Banten | J577: Kota Tangerang | K577: 15157 | L577: 41.586343 | M577: 440000
A578: Jawa Barat | B578: Kab. Indramayu | C578: 45281 | D578: 140.82097 | E578: 149.92853 | F578: 152.2064 | G578: 840000 | I578: Jawa Barat | J578: Kab. Sukabumi | K578: 43359 | L578: 94.089422 | M578: 455000
A579: Jawa Barat | B579: Kab. Kuningan | C579: 45553 | D579: 140.82113 | E579: 150.12668 | F579: 146.46339 | G579: 840000 | I579: Jawa Barat | J579: Kab. Sukabumi | K579: 43358 | L579: 95.073837 | M579: 460000
A580: Jawa Barat | B580: Kab. Kuningan | C580: 45565 | D580: 140.65022 | E580: 149.66338 | F580: 145.03139 | G580: 840000 | I580: DKI Jakarta | J580: Kota Jakarta Utara | K580: 16920 | L580: 19.010401 | M580: 460000
A581: Jawa Barat | B581: Kab. Tasikmalaya | C581: 46168 | D581: 140.67597 | E581: 146.71481 | F581: 137.85331 | G581: 840000 | I581: Jawa Barat | J581: Kab. Sukabumi | K581: 43356 | L581: 96.262891 | M581: 470000
A582: Jawa Barat | B582: Kota Bogor | C582: 16146 | D582: 140.52412 | E582: 132.7559 | F582: 140.51239 | G582: 840000 | I582: Jawa Barat | J582: Kab. Cianjur | K582: 43254 | L582: 81.445288 | M582: 475000
A583: Jawa Barat | B583: Kab. Bogor | C583: 16110 | D583: 141.1277 | E583: 132.69327 | F583: 139.44164 | G583: 845000 | I583: Jawa Barat | J583: Kab. Karawang | K583: 41362 | L583: 61.890582 | M583: 485000
A584: Jawa Barat | B584: Kab. Cirebon | C584: 45612 | D584: 141.97456 | E584: 151.57336 | F584: 149.8145 | G584: 845000 | I584: Jawa Barat | J584: Kab. Sukabumi | K584: 43153 | L584: 95.428761 | M584: 485000
A585: Jawa Barat | B585: Kab. Kuningan | C585: 45513 | D585: 141.16981 | E585: 150.38787 | F585: 146.39517 | G585: 845000 | I585: Jawa Barat | J585: Kab. Sukabumi | K585: 43355 | L585: 101.8614 | M585: 490000
A586: Jawa Barat | B586: Kab. Kuningan | C586: 45516 | D586: 141.23187 | E586: 150.34238 | F586: 145.99521 | G586: 845000 | I586: Jawa Barat | J586: Kab. Sukabumi | K586: 43357 | L586: 104.78021 | M586: 510000
...

Sheet Sheet1
A1: Blibli Elektronik - Kopo Bandung | D1: Jawa Barat - Blibli Elektronik | N1: Jabodetabek - Dekoruma
A2: Blibli Elektronik - Banjaran Bandung
A3: Dekoruma Elektronik - Kalimalang Bekasi | D3: WH | E3: Store | N3: WH | O3: Store
D4: WH Bandung | E4: BE - 1 - BDO | N4: WH Cibinong | O4: DE - 1 BKI
D5: Kiaracondong | E5: Kopo | N5: Cibinong | O5: Kalimalang
D6: https://maps.app.goo.gl/6v79gQL7bjGS5Wr79 | E6: https://maps.app.goo.gl/yqpJkETomQgMRFxu8 | N6: https://maps.app.goo.gl/Ee7ZDBQZ67xspzGg9 | O6: https://maps.app.goo.gl/pCKB2rH92pKezD4n7
D7: -6.936177 | E7: -6.950973 | N7: -6.4727302 | O7: -6.2466437
D8: 107.64238 | E8: 107.58622 | F8: Blibli Elektronik - Kopo Bandung | I8: Blibli Elektronik - Kopo Bandung | N8: 106.86182 | O8: 106.95729 | P8: Dekoruma Elektronik - Kalimalang Bekasi | Q8: Dekoruma Elektronik - Kalimalang Bekasi
D9: Distance (Km) | F9: Minimum Charge (ZONE 2) | N9: Distance (Km) | P9: Minimum Charge (ZONE 2)
A11: Province | B11: City | C11: Postal Code | D11: WH Bandung | E11: BE - 1 - BDO | F11: Blibli Elektronik - Kopo Bandung | G11: Blibli Elektronik - Banjaran Bandung | H11: Dekoruma Elektronik - Kalimalang Bekasi | I11: Regular (3-4 Days) | K11: Province | L11: City | M11: Postal Code | N11: WH Cibinong | O11: DE - 1 BKI | P11: Nextday (1-2 Days) | Q11: Regular (3-4 Days) | T11: Coverage Area | U11: Zone 1 & 2 | V11: Zone 1 | W11: Zone 1 | AC11: Kota Cimahi | AD11: Kota Bandung | AE11: Kab. Bandung Barat | AF11: Kab. Bandung | AG11: Kab. Sumedang | AH11: Kab. Subang | AI11: Kab. Purwakarta | AJ11: Kab. Garut | AK11: Kab. Cianjur | AL11: Kab. Indramayu | AM11: Kab. Tasikmalaya | AN11: Kab. Majalengka | AO11: Kab. Karawang | AP11: Kab. Bogor | AQ11: Kab. Sukabumi | AR11: Kab. Ciamis | AS11: Kota Tasikmalaya | AT11: Kab. Bekasi | AU11: Kota Sukabumi | AV11: Kab. Kuningan | AW11: Kab. Cirebon | AX11: Kota Bogor | AY11: Kota Bekasi | AZ11: Kota Cirebon | BA11: Kota Depok | BB11: Kota Jakarta Timur | BC11: Kota Banjar | BD11: Kab. Pangandaran | BE11: Kota Jakarta Pusat | BF11: Kota Jakarta Selatan | BG11: Kota Jakarta Utara | BH11: Kota Tangerang Selatan | BI11: Kota Jakarta Barat | BJ11: Kota Tangerang | BK11: Kab. Tangerang | BL11: Kab. Lebak | BM11: Kab. Kepulauan Seribu | BN11: Kab. Serang | BO11: Kota Serang | BP11: Kab. Pandeglang | BQ11: Kota Cilegon | BU11: Province | BV11: City | BW11: Postal Code | BX11: Lat | BY11: Long | BZ11: Banjaran
A12: =B12&C12 -> Kab. Lebak42311 | B12: Kab. Lebak | C12: 42311 | D12: 250.70104 | E12: 243.14966 | F12: 1390000 | G12: 1390000 | H12: 705000 | I12: 1390000 | K12: Banten | L12: Kab. Lebak | M12: 42311 | N12: 103.75134 | O12: 119.01643 | P12: 705000 | Q12: 705000 | T12: Category | U12: Nextday Delivery | V12: Trade In Delivery | W12: Lite Install Delivery | X12: Kota Cimahi | Y12: 40534 | Z12: =X12&Y12 -> Kota Cimahi40534 | AA12: Kota Cimahi | AB12: 40534 | AC12: =IFERROR(IF(MATCH(AC$11&$AB12,$Z$12:$Z$1468,0)>0,$AB12,""),"") -> 40534 | AD12: =IFERROR(IF(MATCH(AD$11&$AB12,$Z$12:$Z$1468,0)>0,$AB12,""),"") | AE12: =IFERROR(IF(MATCH(AE$11&$AB12,$Z$12:$Z$1468,0)>0,$AB12,""),"") | AF12: =IFERROR(IF(MATCH(AF$11&$AB12,$Z$12:$Z$1468,0)>0,$AB12,""),"") | AG12: =IFERROR(IF(MATCH(AG$11&$AB12,$Z$12:$Z$1468,0)>0,$AB12,""),"") | AH12: =IFERROR(IF(MATCH(AH$11&$AB12,$Z$12:$Z$1468,0)>0,$AB12,""),"") | AI12: =IFERROR(IF(MATCH(AI$11&$AB12,$Z$12:$Z$1468,0)>0,$AB12,""),"") | AJ12: =IFERROR(IF(MATCH(AJ$11&$AB12,$Z$12:$Z$1468,0)>0,$AB12,""),"") | ... BQ12: =IFERROR(IF(MATCH(BQ$11&$AB12,$Z$12:$Z$1468,0)>0,$AB12,""),"") | BU12: Banten | BV12: Kab. Lebak | BW12: 42311 | BX12: -6.3534552 | BY12: 106.24748 | BZ12: 251.02112
A13: =B13&C13 -> Kab. Lebak42312 | B13: Kab. Lebak | C13: 42312 | D13: 241.49513 | E13: 234.07783 | F13: 1345000 | G13: 1345000 | H13: 655000 | I13: 1345000 | K13: Banten | L13: Kab. Lebak | M13: 42312 | N13: 93.683491 | O13: 108.42315 | P13: 655000 | Q13: 655000 | T13: Dispenser | U13: 75000 | V13: =U13*2 -> 150000 | W13: =U13+15000 -> 90000 | X13: Kota Cimahi | Y13: 40535 | Z13: =X13&Y13 -> Kota Cimahi40535 | AA13: Kota Bandung | AB13: 10110 | AC13: =IFERROR(IF(MATCH(AC$11&$AB13,$Z$12:$Z$1468,0)>0,$AB13,""),"") | AD13: =IFERROR(IF(MATCH(AD$11&$AB13,$Z$12:$Z$1468,0)>0,$AB13,""),"") | AE13: =IFERROR(IF(MATCH(AE$11&$AB13,$Z$12:$Z$1468,0)>0,$AB13,""),"") | AF13: =IFERROR(IF(MATCH(AF$11&$AB13,$Z$12:$Z$1468,0)>0,$AB13,""),"") | AG13: =IFERROR(IF(MATCH(AG$11&$AB13,$Z$12:$Z$1468,0)>0,$AB13,""),"") | AH13: =IFERROR(IF(MATCH(AH$11&$AB13,$Z$12:$Z$1468,0)>0,$AB13,""),"") | AI13: =IFERROR(IF(MATCH(AI$11&$AB13,$Z$12:$Z$1468,0)>0,$AB13,""),"") | AJ13: =IFERROR(IF(MATCH(AJ$11&$AB13,$Z$12:$Z$1468,0)>0,$AB13,""),"") | ... BQ13: =IFERROR(IF(MATCH(BQ$11&$AB13,$Z$12:$Z$1468,0)>0,$AB13,""),"") | BU13: Banten | BV13: Kab. Lebak | BW13: 42312 | BX13: -6.3465331 | BY13: 106.31106 | BZ13: 242.11354
A14: =B14&C14 -> Kab. Lebak42313 | B14: Kab. Lebak | C14: 42313 | D14: 245.37766 | E14: 237.78291 | F14: 1365000 | G14: 1365000 | H14: 680000 | I14: 1365000 | K14: Banten | L14: Kab. Lebak | M14: 42313 | N14: 98.950148 | O14: 115.50688 | P14: 680000 | Q14: 680000 | T14: Home Theather | U14: 75000 | V14: =U14*2 -> 150000 | W14: N/A | X14: Kota Cimahi | Y14: 40514 | Z14: =X14&Y14 -> Kota Cimahi40514 | AA14: Kab. Bandung Barat | AB14: 10120 | AC14: =IFERROR(IF(MATCH(AC$11&$AB14,$Z$12:$Z$1468,0)>0,$AB14,""),"") | AD14: =IFERROR(IF(MATCH(AD$11&$AB14,$Z$12:$Z$1468,0)>0,$AB14,""),"") | AE14: =IFERROR(IF(MATCH(AE$11&$AB14,$Z$12:$Z$1468,0)>0,$AB14,""),"") | AF14: =IFERROR(IF(MATCH(AF$11&$AB14,$Z$12:$Z$1468,0)>0,$AB14,""),"") | AG14: =IFERROR(IF(MATCH(AG$11&$AB14,$Z$12:$Z$1468,0)>0,$AB14,""),"") | AH14: =IFERROR(IF(MATCH(AH$11&$AB14,$Z$12:$Z$1468,0)>0,$AB14,""),"") | AI14: =IFERROR(IF(MATCH(AI$11&$AB14,$Z$12:$Z$1468,0)>0,$AB14,""),"") | AJ14: =IFERROR(IF(MATCH(AJ$11&$AB14,$Z$12:$Z$1468,0)>0,$AB14,""),"") | ... BQ14: =IFERROR(IF(MATCH(BQ$11&$AB14,$Z$12:$Z$1468,0)>0,$AB14,""),"") | BU14: Banten | BV14: Kab. Lebak | BW14: 42313 | BX14: -6.3759972 | BY14: 106.27281 | BZ14: 245.60598
A15: =B15&C15 -> Kab. Lebak42314 | B15: Kab. Lebak | C15: 42314 | D15: 249.36206 | E15: 241.8135 | F15: 1385000 | G15: 1385000 | H15: 700000 | I15: 1385000 | K15: Banten | L15: Kab. Lebak | M15: 42314 | N15: 102.42041 | O15: 117.82385 | P15: 700000 | Q15: 700000 | T15: Water Heater | U15: 75000 | V15: =U15*2 -> 150000 | W15: N/A | X15: Kota Cimahi | Y15: 40522 | Z15: =X15&Y15 -> Kota Cimahi40522 | AA15: Kab. Bandung | AB15: 10130 | AC15: =IFERROR(IF(MATCH(AC$11&$AB15,$Z$12:$Z$1468,0)>0,$AB15,""),"") | AD15: =IFERROR(IF(MATCH(AD$11&$AB15,$Z$12:$Z$1468,0)>0,$AB15,""),"") | AE15: =IFERROR(IF(MATCH(AE$11&$AB15,$Z$12:$Z$1468,0)>0,$AB15,""),"") | AF15: =IFERROR(IF(MATCH(AF$11&$AB15,$Z$12:$Z$1468,0)>0,$AB15,""),"") | AG15: =IFERROR(IF(MATCH(AG$11&$AB15,$Z$12:$Z$1468,0)>0,$AB15,""),"") | AH15: =IFERROR(IF(MATCH(AH$11&$AB15,$Z$12:$Z$1468,0)>0,$AB15,""),"") | AI15: =IFERROR(IF(MATCH(AI$11&$AB15,$Z$12:$Z$1468,0)>0,$AB15,""),"") | AJ15: =IFERROR(IF(MATCH(AJ$11&$AB15,$Z$12:$Z$1468,0)>0,$AB15,""),"") | ... BQ15: =IFERROR(IF(MATCH(BQ$11&$AB15,$Z$12:$Z$1468,0)>0,$AB15,""),"") | BU15: Banten | BV15: Kab. Lebak | BW15: 42314 | BX15: -6.3560275 | BY15: 106.25516 | BZ15: 249.68938
A16: =B16&C16 -> Kab. Lebak42315 | B16: Kab. Lebak | C16: 42315 | D16: 221.64996 | E16: 213.21867 | F16: 1245000 | G16: 1245000 | H16: 640000 | I16: 1245000 | K16: Banten | L16: Kab. Lebak | M16: 42315 | N16: 90.205612 | O16: 120.43982 | P16: 640000 | Q16: 640000 | T16: TV (<= 43") | U16: 75000 | V16: =U16*2 -> 150000 | W16: =U16+15000 -> 90000 | X16: Kota Cimahi | Y16: 40533 | Z16: =X16&Y16 -> Kota Cimahi40533 | AA16: Kab. Sumedang | AB16: 10140 | AC16: =IFERROR(IF(MATCH(AC$11&$AB16,$Z$12:$Z$1468,0)>0,$AB16,""),"") | AD16: =IFERROR(IF(MATCH(AD$11&$AB16,$Z$12:$Z$1468,0)>0,$AB16,""),"") | AE16: =IFERROR(IF(MATCH(AE$11&$AB16,$Z$12:$Z$1468,0)>0,$AB16,""),"") | AF16: =IFERROR(IF(MATCH(AF$11&$AB16,$Z$12:$Z$1468,0)>0,$AB16,""),"") | AG16: =IFERROR(IF(MATCH(AG$11&$AB16,$Z$12:$Z$1468,0)>0,$AB16,""),"") | AH16: =IFERROR(IF(MATCH(AH$11&$AB16,$Z$12:$Z$1468,0)>0,$AB16,""),"") | AI16: =IFERROR(IF(MATCH(AI$11&$AB16,$Z$12:$Z$1468,0)>0,$AB16,""),"") | AJ16: =IFERROR(IF(MATCH(AJ$11&$AB16,$Z$12:$Z$1468,0)>0,$AB16,""),"") | ... BQ16: =IFERROR(IF(MATCH(BQ$11&$AB16,$Z$12:$Z$1468,0)>0,$AB16,""),"") | BU16: Banten | BV16: Kab. Lebak | BW16: 42315 | BX16: -6.6284399 | BY16: 106.34049 | BZ16: 219.82621
A17: =B17&C17 -> Kab. Lebak42316 | B17: Kab. Lebak | C17: 42316 | D17: 248.60982 | E17: 241.13966 | F17: 1380000 | G17: 1380000 | H17: 695000 | I17: 1380000 | K17: Banten | L17: Kab. Lebak | M17: 42316 | N17: 101.05012 | O17: 115.51351 | P17: 695000 | Q17: 695000 | T17: TV (> 43") | U17: 100000 | V17: =U17*2 -> 200000 | W17: =U17+15000 -> 115000 | X17: Kota Cimahi | Y17: 40513 | Z17: =X17&Y17 -> Kota Cimahi40513 | AA17: Kab. Subang | AB17: 10150 | AC17: =IFERROR(IF(MATCH(AC$11&$AB17,$Z$12:$Z$1468,0)>0,$AB17,""),"") | AD17: =IFERROR(IF(MATCH(AD$11&$AB17,$Z$12:$Z$1468,0)>0,$AB17,""),"") | AE17: =IFERROR(IF(MATCH(AE$11&$AB17,$Z$12:$Z$1468,0)>0,$AB17,""),"") | AF17: =IFERROR(IF(MATCH(AF$11&$AB17,$Z$12:$Z$1468,0)>0,$AB17,""),"") | AG17: =IFERROR(IF(MATCH(AG$11&$AB17,$Z$12:$Z$1468,0)>0,$AB17,""),"") | AH17: =IFERROR(IF(MATCH(AH$11&$AB17,$Z$12:$Z$1468,0)>0,$AB17,""),"") | AI17: =IFERROR(IF(MATCH(AI$11&$AB17,$Z$12:$Z$1468,0)>0,$AB17,""),"") | AJ17: =IFERROR(IF(MATCH(AJ$11&$AB17,$Z$12:$Z$1468,0)>0,$AB17,""),"") | ... BQ17: =IFERROR(IF(MATCH(BQ$11&$AB17,$Z$12:$Z$1468,0)>0,$AB17,""),"") | BU17: Banten | BV17: Kab. Lebak | BW17: 42316 | BX17: -6.3402517 | BY17: 106.26692 | BZ17: 249.10884
A18: =B18&C18 -> Kab. Lebak42317 | B18: Kab. Lebak | C18: 42317 | D18: 252.10735 | E18: 244.57856 | F18: 1400000 | G18: 1400000 | H18: 710000 | I18: 1400000 | K18: Banten | L18: Kab. Lebak | M18: 42317 | N18: 104.93787 | O18: 119.72578 | P18: 710000 | Q18: 710000 | T18: Mesin Cuci | U18: 100000 | V18: =U18*2 -> 200000 | W18: =U18+15000 -> 115000 | X18: Kota Cimahi | Y18: 40512 | Z18: =X18&Y18 -> Kota Cimahi40512 | AA18: Kab. Purwakarta | AB18: 10160 | AC18: =IFERROR(IF(MATCH(AC$11&$AB18,$Z$12:$Z$1468,0)>0,$AB18,""),"") | AD18: =IFERROR(IF(MATCH(AD$11&$AB18,$Z$12:$Z$1468,0)>0,$AB18,""),"") | AE18: =IFERROR(IF(MATCH(AE$11&$AB18,$Z$12:$Z$1468,0)>0,$AB18,""),"") | AF18: =IFERROR(IF(MATCH(AF$11&$AB18,$Z$12:$Z$1468,0)>0,$AB18,""),"") | AG18: =IFERROR(IF(MATCH(AG$11&$AB18,$Z$12:$Z$1468,0)>0,$AB18,""),"") | AH18: =IFERROR(IF(MATCH(AH$11&$AB18,$Z$12:$Z$1468,0)>0,$AB18,""),"") | AI18: =IFERROR(IF(MATCH(AI$11&$AB18,$Z$12:$Z$1468,0)>0,$AB18,""),"") | AJ18: =IFERROR(IF(MATCH(AJ$11&$AB18,$Z$12:$Z$1468,0)>0,$AB18,""),"") | ... BQ18: =IFERROR(IF(MATCH(BQ$11&$AB18,$Z$12:$Z$1468,0)>0,$AB18,""),"") | BU18: Banten | BV18: Kab. Lebak | BW18: 42317 | BX18: -6.3449016 | BY18: 106.24192 | BZ18: 252.47598
A19: =B19&C19 -> Kab. Lebak42318 | B19: Kab. Lebak | C19: 42318 | D19: 217.85312 | E19: 209.34994 | F19: 1225000 | G19: 1225000 | H19: 630000 | I19: 1225000 | K19: Banten | L19: Kab. Lebak | M19: 42318 | N19: 88.743924 | O19: 120.28284 | P19: 630000 | Q19: 630000 | T19: AC | U19: 125000 | V19: =U19*2 -> 250000 | W19: N/A | X19: Kota Cimahi | Y19: 40523 | Z19: =X19&Y19 -> Kota Cimahi40523 | AA19: Kab. Garut | AB19: 10210 | AC19: =IFERROR(IF(MATCH(AC$11&$AB19,$Z$12:$Z$1468,0)>0,$AB19,""),"") | AD19: =IFERROR(IF(MATCH(AD$11&$AB19,$Z$12:$Z$1468,0)>0,$AB19,""),"") | AE19: =IFERROR(IF(MATCH(AE$11&$AB19,$Z$12:$Z$1468,0)>0,$AB19,""),"") | AF19: =IFERROR(IF(MATCH(AF$11&$AB19,$Z$12:$Z$1468,0)>0,$AB19,""),"") | AG19: =IFERROR(IF(MATCH(AG$11&$AB19,$Z$12:$Z$1468,0)>0,$AB19,""),"") | AH19: =IFERROR(IF(MATCH(AH$11&$AB19,$Z$12:$Z$1468,0)>0,$AB19,""),"") | AI19: =IFERROR(IF(MATCH(AI$11&$AB19,$Z$12:$Z$1468,0)>0,$AB19,""),"") | AJ19: =IFERROR(IF(MATCH(AJ$11&$AB19,$Z$12:$Z$1468,0)>0,$AB19,""),"") | ... BQ19: =IFERROR(IF(MATCH(BQ$11&$AB19,$Z$12:$Z$1468,0)>0,$AB19,""),"") | BU19: Banten | BV19: Kab. Lebak | BW19: 42318 | BX19: -6.6536226 | BY19: 106.35815 | BZ19: 215.82911
A20: =B20&C20 -> Kab. Lebak42319 | B20: Kab. Lebak | C20: 42319 | D20: 238.46477 | E20: 230.17154 | F20: 1330000 | G20: 1330000 | H20: 700000 | I20: 1330000 | K20: Banten | L20: Kab. Lebak | M20: 42319 | N20: 102.17096 | O20: 128.32245 | P20: 700000 | Q20: 700000 | T20: Kulkas (<320Lt) | U20: 150000 | V20: =U20*2 -> 300000 | W20: =U20+15000 -> 165000 | X20: Kota Cimahi | Y20: 40525 | Z20: =X20&Y20 -> Kota Cimahi40525 | AA20: Kab. Cianjur | AB20: 10220 | AC20: =IFERROR(IF(MATCH(AC$11&$AB20,$Z$12:$Z$1468,0)>0,$AB20,""),"") | AD20: =IFERROR(IF(MATCH(AD$11&$AB20,$Z$12:$Z$1468,0)>0,$AB20,""),"") | AE20: =IFERROR(IF(MATCH(AE$11&$AB20,$Z$12:$Z$1468,0)>0,$AB20,""),"") | AF20: =IFERROR(IF(MATCH(AF$11&$AB20,$Z$12:$Z$1468,0)>0,$AB20,""),"") | AG20: =IFERROR(IF(MATCH(AG$11&$AB20,$Z$12:$Z$1468,0)>0,$AB20,""),"") | AH20: =IFERROR(IF(MATCH(AH$11&$AB20,$Z$12:$Z$1468,0)>0,$AB20,""),"") | AI20: =IFERROR(IF(MATCH(AI$11&$AB20,$Z$12:$Z$1468,0)>0,$AB20,""),"") | AJ20: =IFERROR(IF(MATCH(AJ$11&$AB20,$Z$12:$Z$1468,0)>0,$AB20,""),"") | ... BQ20: =IFERROR(IF(MATCH(BQ$11&$AB20,$Z$12:$Z$1468,0)>0,$AB20,""),"") | BU20: Banten | BV20: Kab. Lebak | BW20: 42319 | BX20: -6.5643956 | BY20: 106.25221 | BZ20: 237.00197
A21: =B21&C21 -> Kab. Lebak42352 | B21: Kab. Lebak | C21: 42352 | D21: 264.04785 | E21: 256.45901 | F21: 1460000 | G21: 1460000 | H21: 775000 | I21: 1460000 | K21: Banten | L21: Kab. Lebak | M21: 42352 | N21: 117.122 | O21: 131.2948 | P21: 775000 | Q21: 775000 | T21: Kulkas (320Lt - Side by Side) | U21: 175000 | V21: =U21*2 -> 350000 | W21: =U21+15000 -> 190000 | X21: Kota Cimahi | Y21: 40521 | Z21: =X21&Y21 -> Kota Cimahi40521 | AA21: Kab. Indramayu | AB21: 10230 | AC21: =IFERROR(IF(MATCH(AC$11&$AB21,$Z$12:$Z$1468,0)>0,$AB21,""),"") | AD21: =IFERROR(IF(MATCH(AD$11&$AB21,$Z$12:$Z$1468,0)>0,$AB21,""),"") | AE21: =IFERROR(IF(MATCH(AE$11&$AB21,$Z$12:$Z$1468,0)>0,$AB21,""),"") | AF21: =IFERROR(IF(MATCH(AF$11&$AB21,$Z$12:$Z$1468,0)>0,$AB21,""),"") | AG21: =IFERROR(IF(MATCH(AG$11&$AB21,$Z$12:$Z$1468,0)>0,$AB21,""),"") | AH21: =IFERROR(IF(MATCH(AH$11&$AB21,$Z$12:$Z$1468,0)>0,$AB21,""),"") | AI21: =IFERROR(IF(MATCH(AI$11&$AB21,$Z$12:$Z$1468,0)>0,$AB21,""),"") | AJ21: =IFERROR(IF(MATCH(AJ$11&$AB21,$Z$12:$Z$1468,0)>0,$AB21,""),"") | ... BQ21: =IFERROR(IF(MATCH(BQ$11&$AB21,$Z$12:$Z$1468,0)>0,$AB21,""),"") | BU21: Banten | BV21: Kab. Lebak | BW21: 42352 | BX21: -6.3305165 | BY21: 106.16986 | BZ21: 264.27516
A22: =B22&C22 -> Kab. Lebak42353 | B22: Kab. Lebak | C22: 42353 | D22: 267.27183 | E22: 259.00922 | F22: 1475000 | G22: 1475000 | H22: 830000 | I22: 1475000 | K22: Banten | L22: Kab. Lebak | M22: 42353 | N22: 128.45247 | O22: 150.61636 | P22: 830000 | Q22: 830000 | X22: Kota Cimahi | Y22: 40532 | Z22: =X22&Y22 -> Kota Cimahi40532 | AA22: Kab. Tasikmalaya | AB22: 10240 | AC22: =IFERROR(IF(MATCH(AC$11&$AB22,$Z$12:$Z$1468,0)>0,$AB22,""),"") | AD22: =IFERROR(IF(MATCH(AD$11&$AB22,$Z$12:$Z$1468,0)>0,$AB22,""),"") | AE22: =IFERROR(IF(MATCH(AE$11&$AB22,$Z$12:$Z$1468,0)>0,$AB22,""),"") | AF22: =IFERROR(IF(MATCH(AF$11&$AB22,$Z$12:$Z$1468,0)>0,$AB22,""),"") | AG22: =IFERROR(IF(MATCH(AG$11&$AB22,$Z$12:$Z$1468,0)>0,$AB22,""),"") | AH22: =IFERROR(IF(MATCH(AH$11&$AB22,$Z$12:$Z$1468,0)>0,$AB22,""),"") | AI22: =IFERROR(IF(MATCH(AI$11&$AB22,$Z$12:$Z$1468,0)>0,$AB22,""),"") | AJ22: =IFERROR(IF(MATCH(AJ$11&$AB22,$Z$12:$Z$1468,0)>0,$AB22,""),"") | ... BQ22: =IFERROR(IF(MATCH(BQ$11&$AB22,$Z$12:$Z$1468,0)>0,$AB22,""),"") | BU22: Banten | BV22: Kab. Lebak | BW22: 42353 | BX22: -6.5079856 | BY22: 106.08753 | BZ22: 265.86571
A23: =B23&C23 -> Kab. Lebak42354 | B23: Kab. Lebak | C23: 42354 | D23: 269.20641 | E23: 260.65004 | F23: 1485000 | G23: 1485000 | H23: 865000 | I23: 1485000 | K23: Banten | L23: Kab. Lebak | M23: 42354 | N23: 135.87003 | O23: 161.28382 | P23: 865000 | Q23: 865000 | X23: Kota Cimahi | Y23: 40524 | Z23: =X23&Y23 -> Kota Cimahi40524 | AA23: Kab. Majalengka | AB23: 10250 | AC23: =IFERROR(IF(MATCH(AC$11&$AB23,$Z$12:$Z$1468,0)>0,$AB23,""),"") | AD23: =IFERROR(IF(MATCH(AD$11&$AB23,$Z$12:$Z$1468,0)>0,$AB23,""),"") | AE23: =IFERROR(IF(MATCH(AE$11&$AB23,$Z$12:$Z$1468,0)>0,$AB23,""),"") | AF23: =IFERROR(IF(MATCH(AF$11&$AB23,$Z$12:$Z$1468,0)>0,$AB23,""),"") | AG23: =IFERROR(IF(MATCH(AG$11&$AB23,$Z$12:$Z$1468,0)>0,$AB23,""),"") | AH23: =IFERROR(IF(MATCH(AH$11&$AB23,$Z$12:$Z$1468,0)>0,$AB23,""),"") | AI23: =IFERROR(IF(MATCH(AI$11&$AB23,$Z$12:$Z$1468,0)>0,$AB23,""),"") | AJ23: =IFERROR(IF(MATCH(AJ$11&$AB23,$Z$12:$Z$1468,0)>0,$AB23,""),"") | ... BQ23: =IFERROR(IF(MATCH(BQ$11&$AB23,$Z$12:$Z$1468,0)>0,$AB23,""),"") | BU23: Banten | BV23: Kab. Lebak | BW23: 42354 | BX23: -6.6019221 | BY23: 106.05226 | BZ23: 266.97651
A24: =B24&C24 -> Kab. Lebak42355 | B24: Kab. Lebak | C24: 42355 | D24: 281.27247 | E24: 272.72325 | F24: 1545000 | G24: 1545000 | H24: 925000 | I24: 1545000 | K24: Banten | L24: Kab. Lebak | M24: 42355 | N24: 147.00686 | O24: 171.18357 | P24: 925000 | Q24: 925000 | X24: Kota Cimahi | Y24: 40531 | Z24: =X24&Y24 -> Kota Cimahi40531 | AA24: Kab. Karawang | AB24: 10260 | AC24: =IFERROR(IF(MATCH(AC$11&$AB24,$Z$12:$Z$1468,0)>0,$AB24,""),"") | AD24: =IFERROR(IF(MATCH(AD$11&$AB24,$Z$12:$Z$1468,0)>0,$AB24,""),"") | AE24: =IFERROR(IF(MATCH(AE$11&$AB24,$Z$12:$Z$1468,0)>0,$AB24,""),"") | AF24: =IFERROR(IF(MATCH(AF$11&$AB24,$Z$12:$Z$1468,0)>0,$AB24,""),"") | AG24: =IFERROR(IF(MATCH(AG$11&$AB24,$Z$12:$Z$1468,0)>0,$AB24,""),"") | AH24: =IFERROR(IF(MATCH(AH$11&$AB24,$Z$12:$Z$1468,0)>0,$AB24,""),"") | AI24: =IFERROR(IF(MATCH(AI$11&$AB24,$Z$12:$Z$1468,0)>0,$AB24,""),"") | AJ24: =IFERROR(IF(MATCH(AJ$11&$AB24,$Z$12:$Z$1468,0)>0,$AB24,""),"") | ... BQ24: =IFERROR(IF(MATCH(BQ$11&$AB24,$Z$12:$Z$1468,0)>0,$AB24,""),"") | BU24: Banten | BV24: Kab. Lebak | BW24: 42355 | BX24: -6.5835949 | BY24: 105.98174 | BZ24: 279.05449
A25: =B25&C25 -> Kab. Lebak42356 | B25: Kab. Lebak | C25: 42356 | D25: 263.88719 | E25: 256.0528 | F25: 1455000 | G25: 1455000 | H25: 785000 | I25: 1455000 | K25: Banten | L25: Kab. Lebak | M25: 42356 | N25: 119.33202 | O25: 136.63478 | P25: 785000 | Q25: 785000 | X25: Kota Cimahi | Y25: 40511 | Z25: =X25&Y25 -> Kota Cimahi40511 | AA25: Kab. Bogor | AB25: 10270 | AC25: =IFERROR(IF(MATCH(AC$11&$AB25,$Z$12:$Z$1468,0)>0,$AB25,""),"") | AD25: =IFERROR(IF(MATCH(AD$11&$AB25,$Z$12:$Z$1468,0)>0,$AB25,""),"") | AE25: =IFERROR(IF(MATCH(AE$11&$AB25,$Z$12:$Z$1468,0)>0,$AB25,""),"") | AF25: =IFERROR(IF(MATCH(AF$11&$AB25,$Z$12:$Z$1468,0)>0,$AB25,""),"") | AG25: =IFERROR(IF(MATCH(AG$11&$AB25,$Z$12:$Z$1468,0)>0,$AB25,""),"") | AH25: =IFERROR(IF(MATCH(AH$11&$AB25,$Z$12:$Z$1468,0)>0,$AB25,""),"") | AI25: =IFERROR(IF(MATCH(AI$11&$AB25,$Z$12:$Z$1468,0)>0,$AB25,""),"") | AJ25: =IFERROR(IF(MATCH(AJ$11&$AB25,$Z$12:$Z$1468,0)>0,$AB25,""),"") | ... BQ25: =IFERROR(IF(MATCH(BQ$11&$AB25,$Z$12:$Z$1468,0)>0,$AB25,""),"") | BU25: Banten | BV25: Kab. Lebak | BW25: 42356 | BX25: -6.3929032 | BY25: 106.14633 | BZ25: 263.553
A26: =B26&C26 -> Kab. Lebak42357 | B26: Kab. Lebak | C26: 42357 | D26: 256.4185 | E26: 248.9363 | F26: 1420000 | G26: 1420000 | H26: 730000 | I26: 1420000 | K26: Banten | L26: Kab. Lebak | M26: 42357 | N26: 108.7982 | O26: 122.44764 | P26: 730000 | Q26: 730000 | X26: Kota Cimahi | Y26: 40526 | Z26: =X26&Y26 -> Kota Cimahi40526 | AA26: Kab. Sukabumi | AB26: 10310 | AC26: =IFERROR(IF(MATCH(AC$11&$AB26,$Z$12:$Z$1468,0)>0,$AB26,""),"") | AD26: =IFERROR(IF(MATCH(AD$11&$AB26,$Z$12:$Z$1468,0)>0,$AB26,""),"") | AE26: =IFERROR(IF(MATCH(AE$11&$AB26,$Z$12:$Z$1468,0)>0,$AB26,""),"") | AF26: =IFERROR(IF(MATCH(AF$11&$AB26,$Z$12:$Z$1468,0)>0,$AB26,""),"") | AG26: =IFERROR(IF(MATCH(AG$11&$AB26,$Z$12:$Z$1468,0)>0,$AB26,""),"") | AH26: =IFERROR(IF(MATCH(AH$11&$AB26,$Z$12:$Z$1468,0)>0,$AB26,""),"") | AI26: =IFERROR(IF(MATCH(AI$11&$AB26,$Z$12:$Z$1468,0)>0,$AB26,""),"") | AJ26: =IFERROR(IF(MATCH(AJ$11&$AB26,$Z$12:$Z$1468,0)>0,$AB26,""),"") | ... BQ26: =IFERROR(IF(MATCH(BQ$11&$AB26,$Z$12:$Z$1468,0)>0,$AB26,""),"") | BU26: Banten | BV26: Kab. Lebak | BW26: 42357 | BX26: -6.3236996 | BY26: 106.2228 | BZ26: 256.88557
A27: =B27&C27 -> Kab. Lebak42361 | B27: Kab. Lebak | C27: 42361 | D27: 247.16615 | E27: 239.1971 | F27: 1375000 | G27: 1375000 | H27: 710000 | I27: 1375000 | K27: Banten | L27: Kab. Lebak | M27: 42361 | N27: 104.9458 | O27: 126.01829 | P27: 710000 | Q27: 710000 | X27: Kota Bandung | Y27: 40614 | Z27: =X27&Y27 -> Kota Bandung40614 | AA27: Kab. Ciamis | AB27: 10320 | AC27: =IFERROR(IF(MATCH(AC$11&$AB27,$Z$12:$Z$1468,0)>0,$AB27,""),"") | AD27: =IFERROR(IF(MATCH(AD$11&$AB27,$Z$12:$Z$1468,0)>0,$AB27,""),"") | AE27: =IFERROR(IF(MATCH(AE$11&$AB27,$Z$12:$Z$1468,0)>0,$AB27,""),"") | AF27: =IFERROR(IF(MATCH(AF$11&$AB27,$Z$12:$Z$1468,0)>0,$AB27,""),"") | AG27: =IFERROR(IF(MATCH(AG$11&$AB27,$Z$12:$Z$1468,0)>0,$AB27,""),"") | AH27: =IFERROR(IF(MATCH(AH$11&$AB27,$Z$12:$Z$1468,0)>0,$AB27,""),"") | AI27: =IFERROR(IF(MATCH(AI$11&$AB27,$Z$12:$Z$1468,0)>0,$AB27,""),"") | AJ27: =IFERROR(IF(MATCH(AJ$11&$AB27,$Z$12:$Z$1468,0)>0,$AB27,""),"") | ... BQ27: =IFERROR(IF(MATCH(BQ$11&$AB27,$Z$12:$Z$1468,0)>0,$AB27,""),"") | BU27: Banten | BV27: Kab. Lebak | BW27: 42361 | BX27: -6.4622218 | BY27: 106.22868 | BZ27: 246.5228
A28: =B28&C28 -> Kab. Lebak42362 | B28: Kab. Lebak | C28: 42362 | D28: 243.103 | E28: 234.85344 | F28: 1355000 | G28: 1355000 | H28: 715000 | I28: 1355000 | K28: Banten | L28: Kab. Lebak | M28: 42362 | N28: 105.60456 | O28: 130.59335 | P28: 715000 | Q28: 715000 | X28: Kota Bandung | Y28: 40295 | Z28: =X28&Y28 -> Kota Bandung40295 | AA28: Kota Tasikmalaya | AB28: 10330 | AC28: =IFERROR(IF(MATCH(AC$11&$AB28,$Z$12:$Z$1468,0)>0,$AB28,""),"") | AD28: =IFERROR(IF(MATCH(AD$11&$AB28,$Z$12:$Z$1468,0)>0,$AB28,""),"") | AE28: =IFERROR(IF(MATCH(AE$11&$AB28,$Z$12:$Z$1468,0)>0,$AB28,""),"") | AF28: =IFERROR(IF(MATCH(AF$11&$AB28,$Z$12:$Z$1468,0)>0,$AB28,""),"") | AG28: =IFERROR(IF(MATCH(AG$11&$AB28,$Z$12:$Z$1468,0)>0,$AB28,""),"") | AH28: =IFERROR(IF(MATCH(AH$11&$AB28,$Z$12:$Z$1468,0)>0,$AB28,""),"") | AI28: =IFERROR(IF(MATCH(AI$11&$AB28,$Z$12:$Z$1468,0)>0,$AB28,""),"") | AJ28: =IFERROR(IF(MATCH(AJ$11&$AB28,$Z$12:$Z$1468,0)>0,$AB28,""),"") | ... BQ28: =IFERROR(IF(MATCH(BQ$11&$AB28,$Z$12:$Z$1468,0)>0,$AB28,""),"") | BU28: Banten | BV28: Kab. Lebak | BW28: 42362 | BX28: -6.5445698 | BY28: 106.22868 | BZ28: 241.75202
A29: =B29&C29 -> Kab. Lebak42363 | B29: Kab. Lebak | C29: 42363 | D29: 254.89297 | E29: 246.30795 | F29: 1410000 | G29: 1410000 | H29: 805000 | I29: 1410000 | K29: Banten | L29: Kab. Lebak | M29: 42363 | N29: 123.33538 | O29: 150.61584 | P29: 805000 | Q29: 805000 | X29: Kota Bandung | Y29: 40292 | Z29: =X29&Y29 -> Kota Bandung40292 | AA29: Kab. Bekasi | AB29: 10340 | AC29: =IFERROR(IF(MATCH(AC$11&$AB29,$Z$12:$Z$1468,0)>0,$AB29,""),"") | AD29: =IFERROR(IF(MATCH(AD$11&$AB29,$Z$12:$Z$1468,0)>0,$AB29,""),"") | AE29: =IFERROR(IF(MATCH(AE$11&$AB29,$Z$12:$Z$1468,0)>0,$AB29,""),"") | AF29: =IFERROR(IF(MATCH(AF$11&$AB29,$Z$12:$Z$1468,0)>0,$AB29,""),"") | AG29: =IFERROR(IF(MATCH(AG$11&$AB29,$Z$12:$Z$1468,0)>0,$AB29,""),"") | AH29: =IFERROR(IF(MATCH(AH$11&$AB29,$Z$12:$Z$1468,0)>0,$AB29,""),"") | AI29: =IFERROR(IF(MATCH(AI$11&$AB29,$Z$12:$Z$1468,0)>0,$AB29,""),"") | AJ29: =IFERROR(IF(MATCH(AJ$11&$AB29,$Z$12:$Z$1468,0)>0,$AB29,""),"") | ... BQ29: =IFERROR(IF(MATCH(BQ$11&$AB29,$Z$12:$Z$1468,0)>0,$AB29,""),"") | BU29: Banten | BV29: Kab. Lebak | BW29: 42363 | BX29: -6.63016 | BY29: 106.13457 | BZ29: 252.59
A30: =B30&C30 -> Kab. Lebak42364 | B30: Kab. Lebak | C30: 42364 | D30: 233.34223 | E30: 225.12287 | F30: 1305000 | G30: 1305000 | H30: 670000 | I30: 1305000 | K30: Banten | L30: Kab. Lebak | M30: 42364 | N30: 96.106192 | O30: 122.20564 | P30: 670000 | Q30: 670000 | X30: Kota Bandung | Y30: 40613 | Z30: =X30&Y30 -> Kota Bandung40613 | AA30: Kota Sukabumi | AB30: 10350 | AC30: =IFERROR(IF(MATCH(AC$11&$AB30,$Z$12:$Z$1468,0)>0,$AB30,""),"") | AD30: =IFERROR(IF(MATCH(AD$11&$AB30,$Z$12:$Z$1468,0)>0,$AB30,""),"") | AE30: =IFERROR(IF(MATCH(AE$11&$AB30,$Z$12:$Z$1468,0)>0,$AB30,""),"") | AF30: =IFERROR(IF(MATCH(AF$11&$AB30,$Z$12:$Z$1468,0)>0,$AB30,""),"") | AG30: =IFERROR(IF(MATCH(AG$11&$AB30,$Z$12:$Z$1468,0)>0,$AB30,""),"") | AH30: =IFERROR(IF(MATCH(AH$11&$AB30,$Z$12:$Z$1468,0)>0,$AB30,""),"") | AI30: =IFERROR(IF(MATCH(AI$11&$AB30,$Z$12:$Z$1468,0)>0,$AB30,""),"") | AJ30: =IFERROR(IF(MATCH(AJ$11&$AB30,$Z$12:$Z$1468,0)>0,$AB30,""),"") | ... BQ30: =IFERROR(IF(MATCH(BQ$11&$AB30,$Z$12:$Z$1468,0)>0,$AB30,""),"") | BU30: Banten | BV30: Kab. Lebak | BW30: 42364 | BX30: -6.5529254 | BY30: 106.28752 | BZ30: 232.08018
A31: =B31&C31 -> Kab. Lebak42371 | B31: Kab. Lebak | C31: 42371 | D31: 230.22013 | E31: 222.3659 | F31: 1290000 | G31: 1290000 | H31: 625000 | I31: 1290000 | K31: Banten | L31: Kab. Lebak | M31: 42371 | N31: 87.377519 | O31: 109.683 | P31: 625000 | Q31: 625000 | X31: Kota Bandung | Y31: 40296 | Z31: =X31&Y31 -> Kota Bandung40296 | AA31: Kab. Kuningan | AB31: 10410 | AC31: =IFERROR(IF(MATCH(AC$11&$AB31,$Z$12:$Z$1468,0)>0,$AB31,""),"") | AD31: =IFERROR(IF(MATCH(AD$11&$AB31,$Z$12:$Z$1468,0)>0,$AB31,""),"") | AE31: =IFERROR(IF(MATCH(AE$11&$AB31,$Z$12:$Z$1468,0)>0,$AB31,""),"") | AF31: =IFERROR(IF(MATCH(AF$11&$AB31,$Z$12:$Z$1468,0)>0,$AB31,""),"") | AG31: =IFERROR(IF(MATCH(AG$11&$AB31,$Z$12:$Z$1468,0)>0,$AB31,""),"") | AH31: =IFERROR(IF(MATCH(AH$11&$AB31,$Z$12:$Z$1468,0)>0,$AB31,""),"") | AI31: =IFERROR(IF(MATCH(AI$11&$AB31,$Z$12:$Z$1468,0)>0,$AB31,""),"") | AJ31: =IFERROR(IF(MATCH(AJ$11&$AB31,$Z$12:$Z$1468,0)>0,$AB31,""),"") | ... BQ31: =IFERROR(IF(MATCH(BQ$11&$AB31,$Z$12:$Z$1468,0)>0,$AB31,""),"") | BU31: Banten | BV31: Kab. Lebak | BW31: 42371 | BX31: -6.4690448 | BY31: 106.33461 | BZ31: 229.86767
A32: =B32&C32 -> Kab. Lebak42372 | B32: Kab. Lebak | C32: 42372 | D32: 218.92389 | E32: 210.69061 | F32: 1230000 | G32: 1230000 | H32: 605000 | I32: 1230000 | K32: Banten | L32: Kab. Lebak | M32: 42372 | N32: 83.491885 | O32: 112.20244 | P32: 605000 | Q32: 605000 | X32: Kota Bandung | Y32: 40612 | Z32: =X32&Y32 -> Kota Bandung40612 | AA32: Kab. Cirebon | AB32: 10420 | AC32: =IFERROR(IF(MATCH(AC$11&$AB32,$Z$12:$Z$1468,0)>0,$AB32,""),"") | AD32: =IFERROR(IF(MATCH(AD$11&$AB32,$Z$12:$Z$1468,0)>0,$AB32,""),"") | AE32: =IFERROR(IF(MATCH(AE$11&$AB32,$Z$12:$Z$1468,0)>0,$AB32,""),"") | AF32: =IFERROR(IF(MATCH(AF$11&$AB32,$Z$12:$Z$1468,0)>0,$AB32,""),"") | AG32: =IFERROR(IF(MATCH(AG$11&$AB32,$Z$12:$Z$1468,0)>0,$AB32,""),"") | AH32: =IFERROR(IF(MATCH(AH$11&$AB32,$Z$12:$Z$1468,0)>0,$AB32,""),"") | AI32: =IFERROR(IF(MATCH(AI$11&$AB32,$Z$12:$Z$1468,0)>0,$AB32,""),"") | AJ32: =IFERROR(IF(MATCH(AJ$11&$AB32,$Z$12:$Z$1468,0)>0,$AB32,""),"") | ... BQ32: =IFERROR(IF(MATCH(BQ$11&$AB32,$Z$12:$Z$1468,0)>0,$AB32,""),"") | BU32: Banten | BV32: Kab. Lebak | BW32: 42372 | BX32: -6.5810815 | BY32: 106.36993 | BZ32: 217.64084
A33: =B33&C33 -> Kab. Lebak42381 | B33: Kab. Lebak | C33: 42381 | D33: 230.62056 | E33: 223.19589 | F33: 1290000 | G33: 1290000 | H33: 605000 | I33: 1290000 | K33: Banten | L33: Kab. Lebak | M33: 42381 | N33: 83.128826 | O33: 99.714709 | P33: 605000 | Q33: 605000 | X33: Kota Bandung | Y33: 40615 | Z33: =X33&Y33 -> Kota Bandung40615 | AA33: Kota Bogor | AB33: 10430 | AC33: =IFERROR(IF(MATCH(AC$11&$AB33,$Z$12:$Z$1468,0)>0,$AB33,""),"") | AD33: =IFERROR(IF(MATCH(AD$11&$AB33,$Z$12:$Z$1468,0)>0,$AB33,""),"") | AE33: =IFERROR(IF(MATCH(AE$11&$AB33,$Z$12:$Z$1468,0)>0,$AB33,""),"") | AF33: =IFERROR(IF(MATCH(AF$11&$AB33,$Z$12:$Z$1468,0)>0,$AB33,""),"") | AG33: =IFERROR(IF(MATCH(AG$11&$AB33,$Z$12:$Z$1468,0)>0,$AB33,""),"") | AH33: =IFERROR(IF(MATCH(AH$11&$AB33,$Z$12:$Z$1468,0)>0,$AB33,""),"") | AI33: =IFERROR(IF(MATCH(AI$11&$AB33,$Z$12:$Z$1468,0)>0,$AB33,""),"") | AJ33: =IFERROR(IF(MATCH(AJ$11&$AB33,$Z$12:$Z$1468,0)>0,$AB33,""),"") | ... BQ33: =IFERROR(IF(MATCH(BQ$11&$AB33,$Z$12:$Z$1468,0)>0,$AB33,""),"") | BU33: Banten | BV33: Kab. Lebak | BW33: 42381 | BX33: -6.3754256 | BY33: 106.36993 | BZ33: 231.23243
... A52: =B52&C52 -> Kab. Pandeglang42261 | B52: Kab. Pandeglang | C52: 42261 | D52: 295.16655 | E52: 287.4394 | F52: 1615000 | G52: 1615000 | H52: 930000 | I52: 1615000 | K52: Banten | L52: Kab. Pandeglang | M52: 42261 | N52: 148.84995 | O52: 161.94461 | P52: 930000 | Q52: 930000 | X52: Kota Bandung | Y52: 40267 | Z52: =X52&Y52 -> Kota Bandung40267 | AA52: Kota Cilegon | AB52: 10740 | AC52: =IFERROR(IF(MATCH(AC$11&$AB52,$Z$12:$Z$1468,0)>0,$AB52,""),"") | AD52: =IFERROR(IF(MATCH(AD$11&$AB52,$Z$12:$Z$1468,0)>0,$AB52,""),"") | AE52: =IFERROR(IF(MATCH(AE$11&$AB52,$Z$12:$Z$1468,0)>0,$AB52,""),"") | AF52: =IFERROR(IF(MATCH(AF$11&$AB52,$Z$12:$Z$1468,0)>0,$AB52,""),"") | AG52: =IFERROR(IF(MATCH(AG$11&$AB52,$Z$12:$Z$1468,0)>0,$AB52,""),"") | AH52: =IFERROR(IF(MATCH(AH$11&$AB52,$Z$12:$Z$1468,0)>0,$AB52,""),"") | AI52: =IFERROR(IF(MATCH(AI$11&$AB52,$Z$12:$Z$1468,0)>0,$AB52,""),"") | AJ52: =IFERROR(IF(MATCH(AJ$11&$AB52,$Z$12:$Z$1468,0)>0,$AB52,""),"") | ... BQ52: =IFERROR(IF(MATCH(BQ$11&$AB52,$Z$12:$Z$1468,0)>0,$AB52,""),"") | BU52: Banten | BV52: Kab. Pandeglang | BW52: 42261 | BX52: -6.295369 | BY52: 105.98174 | BZ52: 295.06142
A53: =B53&C53 -> Kab. Pandeglang42262 | B53: Kab. Pandeglang | C53: 42262 | D53: 299.49867 | E53: 291.51119 | F53: 1635000 | G53: 1635000 | H53: 965000 | I53: 1635000 | K53: Banten | L53: Kab. Pandeglang | M53: 42262 | N53: 155.69812 | O53: 171.61222 | P53: 965000 | Q53: 965000 | X53: Kota Bandung | Y53: 40266 | Z53: =X53&Y53 -> Kota Bandung40266 | AB53: 10750 | AC53: =IFERROR(IF(MATCH(AC$11&$AB53,$Z$12:$Z$1468,0)>0,$AB53,""),"") | AD53: =IFERROR(IF(MATCH(AD$11&$AB53,$Z$12:$Z$1468,0)>0,$AB53,""),"") | AE53: =IFERROR(IF(MATCH(AE$11&$AB53,$Z$12:$Z$1468,0)>0,$AB53,""),"") | AF53: =IFERROR(IF(MATCH(AF$11&$AB53,$Z$12:$Z$1468,0)>0,$AB53,""),"") | AG53: =IFERROR(IF(MATCH(AG$11&$AB53,$Z$12:$Z$1468,0)>0,$AB53,""),"") | AH53: =IFERROR(IF(MATCH(AH$11&$AB53,$Z$12:$Z$1468,0)>0,$AB53,""),"") | AI53: =IFERROR(IF(MATCH(AI$11&$AB53,$Z$12:$Z$1468,0)>0,$AB53,""),"") | AJ53: =IFERROR(IF(MATCH(AJ$11&$AB53,$Z$12:$Z$1468,0)>0,$AB53,""),"") | ... BQ53: =IFERROR(IF(MATCH(BQ$11&$AB53,$Z$12:$Z$1468,0)>0,$AB53,""),"") | BU53: Banten | BV53: Kab. Pandeglang | BW53: 42262 | BX53: -6.3638216 | BY53: 105.92886 | BZ53: 298.77296
A54: =B54&C54 -> Kab. Pandeglang42263 | B54: Kab. Pandeglang | C54: 42263 | D54: 308.39769 | E54: 300.49649 | F54: 1680000 | G54: 1680000 | H54: 1005000 | I54: 1680000 | K54: Banten | L54: Kab. Pandeglang | M54: 42263 | N54: 163.48394 | O54: 177.72796 | P54: 1005000 | Q54: 1005000 | X54: Kota Bandung | Y54: 40192 | Z54: =X54&Y54 -> Kota Bandung40192 | AB54: 11110 | AC54: =IFERROR(IF(MATCH(AC$11&$AB54,$Z$12:$Z$1468,0)>0,$AB54,""),"") | AD54: =IFERROR(IF(MATCH(AD$11&$AB54,$Z$12:$Z$1468,0)>0,$AB54,""),"") | AE54: =IFERROR(IF(MATCH(AE$11&$AB54,$Z$12:$Z$1468,0)>0,$AB54,""),"") | AF54: =IFERROR(IF(MATCH(AF$11&$AB54,$Z$12:$Z$1468,0)>0,$AB54,""),"") | AG54: =IFERROR(IF(MATCH(AG$11&$AB54,$Z$12:$Z$1468,0)>0,$AB54,""),"") | AH54: =IFERROR(IF(MATCH(AH$11&$AB54,$Z$12:$Z$1468,0)>0,$AB54,""),"") | AI54: =IFERROR(IF(MATCH(AI$11&$AB54,$Z$12:$Z$1468,0)>0,$AB54,""),"") | AJ54: =IFERROR(IF(MATCH(AJ$11&$AB54,$Z$12:$Z$1468,0)>0,$AB54,""),"") | ... BQ54: =IFERROR(IF(MATCH(BQ$11&$AB54,$Z$12:$Z$1468,0)>0,$AB54,""),"") | BU54: Banten | BV54: Kab. Pandeglang | BW54: 42263 | BX54: -6.318846 | BY54: 105.88775 | BZ54: 307.87637
A55: =B55&C55 -> Kab. Pandeglang42264 | B55: Kab. Pandeglang | C55: 42264 | D55: 315.58305 | E55: 307.82896 | F55: 1715000 | G55: 1715000 | H55: 1035000 | I55: 1715000 | K55: Banten | L55: Kab. Pandeglang | M55: 42264 | N55: 169.19632 | O55: 181.2343 | P55: 1035000 | Q55: 1035000 | X55: Kota Bandung | Y55: 40272 | Z55: =X55&Y55 -> Kota Bandung40272 | AB55: 11120 | AC55: =IFERROR(IF(MATCH(AC$11&$AB55,$Z$12:$Z$1468,0)>0,$AB55,""),"") | AD55: =IFERROR(IF(MATCH(AD$11&$AB55,$Z$12:$Z$1468,0)>0,$AB55,""),"") | AE55: =IFERROR(IF(MATCH(AE$11&$AB55,$Z$12:$Z$1468,0)>0,$AB55,""),"") | AF55: =IFERROR(IF(MATCH(AF$11&$AB55,$Z$12:$Z$1468,0)>0,$AB55,""),"") | AG55: =IFERROR(IF(MATCH(AG$11&$AB55,$Z$12:$Z$1468,0)>0,$AB55,""),"") | AH55: =IFERROR(IF(MATCH(AH$11&$AB55,$Z$12:$Z$1468,0)>0,$AB55,""),"") | AI55: =IFERROR(IF(MATCH(AI$11&$AB55,$Z$12:$Z$1468,0)>0,$AB55,""),"") | AJ55: =IFERROR(IF(MATCH(AJ$11&$AB55,$Z$12:$Z$1468,0)>0,$AB55,""),"") | ... BQ55: =IFERROR(IF(MATCH(BQ$11&$AB55,$Z$12:$Z$1468,0)>0,$AB55,""),"") | BU55: Banten | BV55: Kab. Pandeglang | BW55: 42264 | BX55: -6.2579364 | BY55: 105.86426 | BZ55: 315.40468
A56: =B56&C56 -> Kab. Pandeglang42265 | B56: Kab. Pandeglang | C56: 42265 | D56: 306.33624 | E56: 297.98636 | F56: 1670000 | G56: 1670000 | H56: 1025000 | I56: 1670000 | K56: Banten | L56: Kab. Pandeglang | M56: 42265 | N56: 167.2714 | O56: 187.02934 | P56: 1025000 | Q56: 1025000 | X56: Kota Bandung | Y56: 40193 | Z56: =X56&Y56 -> Kota Bandung40193 | AB56: 11130 | AC56: =IFERROR(IF(MATCH(AC$11&$AB56,$Z$12:$Z$1468,0)>0,$AB56,""),"") | AD56: =IFERROR(IF(MATCH(AD$11&$AB56,$Z$12:$Z$1468,0)>0,$AB56,""),"") | AE56: =IFERROR(IF(MATCH(AE$11&$AB56,$Z$12:$Z$1468,0)>0,$AB56,""),"") | AF56: =IFERROR(IF(MATCH(AF$11&$AB56,$Z$12:$Z$1468,0)>0,$AB56,""),"") | AG56: =IFERROR(IF(MATCH(AG$11&$AB56,$Z$12:$Z$1468,0)>0,$AB56,""),"") | AH56: =IFERROR(IF(MATCH(AH$11&$AB56,$Z$12:$Z$1468,0)>0,$AB56,""),"") | AI56: =IFERROR(IF(MATCH(AI$11&$AB56,$Z$12:$Z$1468,0)>0,$AB56,""),"") | AJ56: =IFERROR(IF(MATCH(AJ$11&$AB56,$Z$12:$Z$1468,0)>0,$AB56,""),"") | ... BQ56: =IFERROR(IF(MATCH(BQ$11&$AB56,$Z$12:$Z$1468,0)>0,$AB56,""),"") | BU56: Banten | BV56: Kab. Pandeglang | BW56: 42265 | BX56: -6.4743279 | BY56: 105.85252 | BZ56: 304.66801
A57: =B57&C57 -> Kab. Pandeglang42271 | B57: Kab. Pandeglang | C57: 42271 | D57: 279.54575 | E57: 271.65509 | F57: 1535000 | G57: 1535000 | H57: 865000 | I57: 1535000 | K57: Banten | L57: Kab. Pandeglang | M57: 42271 | N57: 135.16015 | O57: 151.56462 | P57: 865000 | Q57: 865000 | X57: Kota Bandung | Y57: 40264 | Z57: =X57&Y57 -> Kota Bandung40264 | AB57: 11140 | AC57: =IFERROR(IF(MATCH(AC$11&$AB57,$Z$12:$Z$1468,0)>0,$AB57,""),"") | AD57: =IFERROR(IF(MATCH(AD$11&$AB57,$Z$12:$Z$1468,0)>0,$AB57,""),"") | AE57: =IFERROR(IF(MATCH(AE$11&$AB57,$Z$12:$Z$1468,0)>0,$AB57,""),"") | AF57: =IFERROR(IF(MATCH(AF$11&$AB57,$Z$12:$Z$1468,0)>0,$AB57,""),"") | AG57: =IFERROR(IF(MATCH(AG$11&$AB57,$Z$12:$Z$1468,0)>0,$AB57,""),"") | AH57: =IFERROR(IF(MATCH(AH$11&$AB57,$Z$12:$Z$1468,0)>0,$AB57,""),"") | AI57: =IFERROR(IF(MATCH(AI$11&$AB57,$Z$12:$Z$1468,0)>0,$AB57,""),"") | AJ57: =IFERROR(IF(MATCH(AJ$11&$AB57,$Z$12:$Z$1468,0)>0,$AB57,""),"") | ... BQ57: =IFERROR(IF(MATCH(BQ$11&$AB57,$Z$12:$Z$1468,0)>0,$AB57,""),"") | BU57: Banten | BV57: Kab. Pandeglang | BW57: 42271 | BX57: -6.3753451 | BY57: 106.05226 | BZ57: 279.06709
A58: =B58&C58 -> Kab. Pandeglang42272 | B58: Kab. Pandeglang | C58: 42272 | D58: 285.59241 | E58: 277.66334 | F58: 1565000 | G58: 1565000 | H58: 895000 | I58: 1565000 | K58: Banten | L58: Kab. Pandeglang | M58: 42272 | N58: 141.47465 | O58: 157.80621 | P58: 895000 | Q58: 895000 | X58: Kota Bandung | Y58: 40618 | Z58: =X58&Y58 -> Kota Bandung40618 | AB58: 11150 | AC58: =IFERROR(IF(MATCH(AC$11&$AB58,$Z$12:$Z$1468,0)>0,$AB58,""),"") | AD58: =IFERROR(IF(MATCH(AD$11&$AB58,$Z$12:$Z$1468,0)>0,$AB58,""),"") | AE58: =IFERROR(IF(MATCH(AE$11&$AB58,$Z$12:$Z$1468,0)>0,$AB58,""),"") | AF58: =IFERROR(IF(MATCH(AF$11&$AB58,$Z$12:$Z$1468,0)>0,$AB58,""),"") | AG58: =IFERROR(IF(MATCH(AG$11&$AB58,$Z$12:$Z$1468,0)>0,$AB58,""),"") | AH58: =IFERROR(IF(MATCH(AH$11&$AB58,$Z$12:$Z$1468,0)>0,$AB58,""),"") | AI58: =IFERROR(IF(MATCH(AI$11&$AB58,$Z$12:$Z$1468,0)>0,$AB58,""),"") | AJ58: =IFERROR(IF(MATCH(AJ$11&$AB58,$Z$12:$Z$1468,0)>0,$AB58,""),"") | ... BQ58: =IFERROR(IF(MATCH(BQ$11&$AB58,$Z$12:$Z$1468,0)>0,$AB58,""),"") | BU58: Banten | BV58: Kab. Pandeglang | BW58: 42272 | BX58: -6.3739864 | BY58: 106.01406 | BZ58: 285.0175
A59: =B59&C59 -> Kab. Pandeglang42273 | B59: Kab. Pandeglang | C59: 42273 | D59: 293.03958 | E59: 284.98004 | F59: 1605000 | G59: 1605000 | H59: 940000 | I59: 1605000 | K59: Banten | L59: Kab. Pandeglang | M59: 42273 | N59: 150.26669 | O59: 167.55598 | P59: 940000 | Q59: 940000 | X59: Kota Bandung | Y59: 40125 | Z59: =X59&Y59 -> Kota Bandung40125 | AB59: 11160 | AC59: =IFERROR(IF(MATCH(AC$11&$AB59,$Z$12:$Z$1468,0)>0,$AB59,""),"") | AD59: =IFERROR(IF(MATCH(AD$11&$AB59,$Z$12:$Z$1468,0)>0,$AB59,""),"") | AE59: =IFERROR(IF(MATCH(AE$11&$AB59,$Z$12:$Z$1468,0)>0,$AB59,""),"") | AF59: =IFERROR(IF(MATCH(AF$11&$AB59,$Z$12:$Z$1468,0)>0,$AB59,""),"") | AG59: =IFERROR(IF(MATCH(AG$11&$AB59,$Z$12:$Z$1468,0)>0,$AB59,""),"") | AH59: =IFERROR(IF(MATCH(AH$11&$AB59,$Z$12:$Z$1468,0)>0,$AB59,""),"") | AI59: =IFERROR(IF(MATCH(AI$11&$AB59,$Z$12:$Z$1468,0)>0,$AB59,""),"") | AJ59: =IFERROR(IF(MATCH(AJ$11&$AB59,$Z$12:$Z$1468,0)>0,$AB59,""),"") | ... BQ59: =IFERROR(IF(MATCH(BQ$11&$AB59,$Z$12:$Z$1468,0)>0,$AB59,""),"") | BU59: Banten | BV59: Kab. Pandeglang | BW59: 42273 | BX59: -6.3988946 | BY59: 105.95824 | BZ59: 292.13917
...

Sheet Distance
A2: Free Shipping | D2: 7 | E2: 7 | F2: 10
A3: Province | B3: City | C3: Postal Code | D3: Blibli Elektronik - Kopo Bandung | E3: Blibli Elektronik - Banjaran Bandung | F3: Dekoruma Elektronik - Kalimalang Bekasi
A4: =B4&C4 -> Kab. Lebak42311 | B4: Kab. Lebak | C4: 42311 | D4: 243.14966 | E4: 251.02112 | F4: 119.01643
A5: =B5&C5 -> Kab. Lebak42312 | B5: Kab. Lebak | C5: 42312 | D5: 234.07783 | E5: 242.11354 | F5: 108.42315
A6: =B6&C6 -> Kab. Lebak42313 | B6: Kab. Lebak | C6: 42313 | D6: 237.78291 | E6: 245.60598 | F6: 115.50688
A7: =B7&C7 -> Kab. Lebak42314 | B7: Kab. Lebak | C7: 42314 | D7: 241.8135 | E7: 249.68938 | F7: 117.82385
A8: =B8&C8 -> Kab. Lebak42315 | B8: Kab. Lebak | C8: 42315 | D8: 213.21867 | E8: 219.82621 | F8: 120.43982
A9: =B9&C9 -> Kab. Lebak42316 | B9: Kab. Lebak | C9: 42316 | D9: 241.13966 | E9: 249.10884 | F9: 115.51351
A10: =B10&C10 -> Kab. Lebak42317 | B10: Kab. Lebak | C10: 42317 | D10: 244.57856 | E10: 252.47598 | F10: 119.72578
A11: =B11&C11 -> Kab. Lebak42318 | B11: Kab. Lebak | C11: 42318 | D11: 209.34994 | E11: 215.82911 | F11: 120.28284
A12: =B12&C12 -> Kab. Lebak42319 | B12: Kab. Lebak | C12: 42319 | D12: 230.17154 | E12: 237.00197 | F12: 128.32245
A13: =B13&C13 -> Kab. Lebak42352 | B13: Kab. Lebak | C13: 42352 | D13: 256.45901 | E13: 264.27516 | F13: 131.2948
A14: =B14&C14 -> Kab. Lebak42353 | B14: Kab. Lebak | C14: 42353 | D14: 259.00922 | E14: 265.86571 | F14: 150.61636
A15: =B15&C15 -> Kab. Lebak42354 | B15: Kab. Lebak | C15: 42354 | D15: 260.65004 | E15: 266.97651 | F15: 161.28382
... A1460: =B1460&C1460 -> Kota Tasikmalaya46416 | B1460: Kota Tasikmalaya | C1460: 46416 | D1460: 110.34695 | E1460: 101.27488 | F1460: 266.13673
